<?xml version="1.0"?>
<robot name="NeetBot" xmlns:xacro="http://ros.org/wiki/xacro">
  <xacro:include filename="$(find sim_model)/xacro/ydlidar_x4.xacro"/>

  <material name="body_color">
    <color rgba="1.0 1.0 0.9 2.0"/>
  </material>
  <material name="wheel_color">
    <color rgba="1.0 0.5 0.0 2.0"/>
  </material>
  <material name="ball_color">
    <color rgba="0.0 1.0 0.5 2.0"/>
  </material>

  <xacro:macro name="wheel_macro" params="parent prefix xyz">
    <joint name="${prefix}_joint" type="continuous">
      <origin xyz="${xyz}" rpy="${radians(-90)} 0 0"/>
      <parent link="${parent}"/>
      <child  link="${prefix}_link"/>
      <axis xyz="0 0 1" />
      <limit velocity="15.0" effort="1.25" />
      <dynamics damping="0.05"/>
    </joint>
    <transmission name="${prefix}_trans" type="SimpleTransmission">
      <type>transmission_interface/SimpleTransmission</type>
        <actuator name="${prefix}_motor">
          <mechanicalReduction>1</mechanicalReduction>
        </actuator>
      <joint name="${prefix}_joint">
        <hardwareInterface>hardware_interface/VelocityJointInterface</hardwareInterface>
      </joint>
    </transmission>
    <link name="${prefix}_link">
      <visual>
        <geometry>
          <cylinder radius="0.074" length="0.02" />
        </geometry>
        <material name="wheel_color"/>
      </visual>
      <collision>
        <geometry>
          <cylinder radius="0.074" length="0.02" />
        </geometry>
      </collision>
      <inertial>
        <origin xyz="0 0 0" rpy="0 0 0"/>
        <mass value="0.1"/>
       <inertia ixx="0.0001" ixy="0.0" ixz="0.0" iyy="0.0001" iyz="0.0" izz="0.0001"/>
      </inertial>
    </link>
    <gazebo reference="${prefix}_link">
      <material>Gazebo/Orange</material>
      <mu1 value="2.5" />
      <mu2 value="2.5" />
      <kp value="50000" />
      <kd value="10" />
    </gazebo>
  </xacro:macro> 

  <link name="base_link"/>

  <xacro:macro name="ball_macro" params="parent prefix xyz">
    <joint name="${prefix}_joint" type="continuous">
      <origin xyz="${xyz}" rpy="0 0 0"/>
      <parent link="${parent}"/>
      <child  link="${prefix}_link"/>
    </joint>
    <link name="${prefix}_link">
      <visual>
        <geometry>
          <sphere radius="0.02"/>
        </geometry>
        <material name="ball_color"/>
      </visual>
      <collision>
        <geometry>
          <sphere radius="0.02" />
        </geometry>
      </collision>
      <inertial>
        <origin xyz="0 0 0" rpy="0 0 0"/>
        <mass value="0.05"/>
        <inertia ixx="0.001" ixy="0.0" ixz="0.0" iyy="0.001" iyz="0.0" izz="0.001"/>
      </inertial>
    </link>
    <gazebo reference="${prefix}_link">
      <material>Gazebo/White</material>
      <mu1 value="0.0"/>
      <mu2 value="0.0"/>
      <splip1 value="1.0"/>
      <splip2 value="1.0"/>
    </gazebo>
  </xacro:macro> 

  <joint name="body_joint" type="fixed">
    <parent link="base_link"/>
    <child  link="body_link"/>
    <origin xyz="0.0 0 0.2425" rpy="0 0 0"/>
  </joint>
  <link name="body_link">
    <visual>
      <origin xyz="0 0 0" rpy="0 0 0" />
      <geometry>
        <cylinder radius="0.125" length="0.115"/>
      </geometry>
      <material name="body_color"/>
    </visual>
    <collision>
      <origin xyz="0 0 0" rpy="0 0 0" />
      <geometry>
        <cylinder radius="0.125" length="0.115" />
      </geometry>
    </collision>
    <inertial>
      <origin xyz="0 0 0" rpy="0 0 0"/>
      <mass value="0.25"/>
      <inertia ixx="0.001" ixy="0.0" ixz="0.0" iyy="0.001" iyz="0.0" izz="0.001"/>
    </inertial>
  </link>
  <gazebo reference="body_link">
    <material>Gazebo/White</material>
  </gazebo>


  <joint name="body_joint2" type="fixed">
    <parent link="base_link"/>
    <child  link="body_link2"/>
    <origin xyz="0.0 0 0.1075" rpy="0 0 0"/>
  </joint>
  <link name="body_link2">
    <visual>
      <origin xyz="0 0 0" rpy="0 0 0" />
      <geometry>
        <box size="0.20 0.170 0.155"/>
      </geometry>
      <material name="body_color"/>
    </visual>
    <collision>
      <origin xyz="0 0 0" rpy="0 0 0" />
      <geometry>
        <box size="0.25 0.170 0.155"/>
      </geometry>
    </collision>
    <inertial>
      <origin xyz="0 0 0" rpy="0 0 0"/>
      <mass value="1.25"/>
      <inertia ixx="0.001" ixy="0.0" ixz="0.0" iyy="0.001" iyz="0.0" izz="0.001"/>
    </inertial>
  </link>
  <gazebo reference="body_link2">
    <material>Gazebo/White</material>
  </gazebo>


  <xacro:wheel_macro prefix="left_wheel"  parent="base_link" xyz="0 0.1085 0.074"/>
  <xacro:wheel_macro prefix="right_wheel" parent="base_link" xyz="0 -0.1085 0.074"/>
  <xacro:ball_macro prefix="front_ball" parent="base_link" xyz="0.095 0.0 0.0201"/>
  <xacro:ball_macro prefix="back_ball" parent="base_link" xyz="-0.095 0.0 0.0201"/>
  <xacro:laser_macro prefix="laser" parent="base_link" xyz="0.0 0.0 0.323"/>

  <gazebo>
    <plugin name="gazebo_ros_control" filename="libgazebo_ros_control.so">
      <robotNamespace>/neet_bot</robotNamespace>
    </plugin>
  </gazebo>
</robot>
